<frozen importlib._bootstrap>:219: RuntimeWarning: scipy._lib.messagestream.MessageStream size changed, may indicate binary incompatibility. Expected 56 from C header, got 64 from PyObject
<frozen importlib._bootstrap>:219: RuntimeWarning: scipy._lib.messagestream.MessageStream size changed, may indicate binary incompatibility. Expected 56 from C header, got 64 from PyObject
Exception ignored in: <Finalize object, dead>
Traceback (most recent call last):
  File "/home/ekavvas/.conda/envs/mb_py385/lib/python3.8/multiprocessing/util.py", line 224, in __call__
    res = self._callback(*self._args, **self._kwargs)
  File "/home/ekavvas/.conda/envs/mb_py385/lib/python3.8/site-packages/joblib/externals/loky/backend/synchronize.py", line 102, in _cleanup
    sem_unlink(name)
FileNotFoundError: [Errno 2] No such file or directory
Exception ignored in: <Finalize object, dead>
Traceback (most recent call last):
  File "/home/ekavvas/.conda/envs/mb_py385/lib/python3.8/multiprocessing/util.py", line 224, in __call__
    res = self._callback(*self._args, **self._kwargs)
  File "/home/ekavvas/.conda/envs/mb_py385/lib/python3.8/site-packages/joblib/externals/loky/backend/synchronize.py", line 102, in _cleanup
    sem_unlink(name)
FileNotFoundError: [Errno 2] No such file or directory
Exception ignored in: <Finalize object, dead>
Traceback (most recent call last):
  File "/home/ekavvas/.conda/envs/mb_py385/lib/python3.8/multiprocessing/util.py", line 224, in __call__
    res = self._callback(*self._args, **self._kwargs)
  File "/home/ekavvas/.conda/envs/mb_py385/lib/python3.8/site-packages/joblib/externals/loky/backend/synchronize.py", line 102, in _cleanup
    sem_unlink(name)
FileNotFoundError: [Errno 2] No such file or directory
Exception ignored in: <Finalize object, dead>
Traceback (most recent call last):
  File "/home/ekavvas/.conda/envs/mb_py385/lib/python3.8/multiprocessing/util.py", line 224, in __call__
    res = self._callback(*self._args, **self._kwargs)
  File "/home/ekavvas/.conda/envs/mb_py385/lib/python3.8/site-packages/joblib/externals/loky/backend/synchronize.py", line 102, in _cleanup
    sem_unlink(name)
FileNotFoundError: [Errno 2] No such file or directory
Exception ignored in: <Finalize object, dead>
Traceback (most recent call last):
  File "/home/ekavvas/.conda/envs/mb_py385/lib/python3.8/multiprocessing/util.py", line 224, in __call__
    res = self._callback(*self._args, **self._kwargs)
  File "/home/ekavvas/.conda/envs/mb_py385/lib/python3.8/site-packages/joblib/externals/loky/backend/synchronize.py", line 102, in _cleanup
    sem_unlink(name)
FileNotFoundError: [Errno 2] No such file or directory
Exception ignored in: <Finalize object, dead>
Traceback (most recent call last):
  File "/home/ekavvas/.conda/envs/mb_py385/lib/python3.8/multiprocessing/util.py", line 224, in __call__
    res = self._callback(*self._args, **self._kwargs)
  File "/home/ekavvas/.conda/envs/mb_py385/lib/python3.8/site-packages/joblib/externals/loky/backend/synchronize.py", line 102, in _cleanup
    sem_unlink(name)
FileNotFoundError: [Errno 2] No such file or directory
Exception ignored in: <Finalize object, dead>
Traceback (most recent call last):
  File "/home/ekavvas/.conda/envs/mb_py385/lib/python3.8/multiprocessing/util.py", line 224, in __call__
    res = self._callback(*self._args, **self._kwargs)
  File "/home/ekavvas/.conda/envs/mb_py385/lib/python3.8/site-packages/joblib/externals/loky/backend/synchronize.py", line 102, in _cleanup
    sem_unlink(name)
FileNotFoundError: [Errno 2] No such file or directory
Exception ignored in: <Finalize object, dead>
Traceback (most recent call last):
  File "/home/ekavvas/.conda/envs/mb_py385/lib/python3.8/multiprocessing/util.py", line 224, in __call__
    res = self._callback(*self._args, **self._kwargs)
  File "/home/ekavvas/.conda/envs/mb_py385/lib/python3.8/site-packages/joblib/externals/loky/backend/synchronize.py", line 102, in _cleanup
    sem_unlink(name)
FileNotFoundError: [Errno 2] No such file or directory
Exception ignored in: <Finalize object, dead>
Traceback (most recent call last):
  File "/home/ekavvas/.conda/envs/mb_py385/lib/python3.8/multiprocessing/util.py", line 224, in __call__
    res = self._callback(*self._args, **self._kwargs)
  File "/home/ekavvas/.conda/envs/mb_py385/lib/python3.8/site-packages/joblib/externals/loky/backend/synchronize.py", line 102, in _cleanup
    sem_unlink(name)
FileNotFoundError: [Errno 2] No such file or directory
Exception ignored in: <Finalize object, dead>
Traceback (most recent call last):
  File "/home/ekavvas/.conda/envs/mb_py385/lib/python3.8/multiprocessing/util.py", line 224, in __call__
    res = self._callback(*self._args, **self._kwargs)
  File "/home/ekavvas/.conda/envs/mb_py385/lib/python3.8/site-packages/joblib/externals/loky/backend/synchronize.py", line 102, in _cleanup
    sem_unlink(name)
FileNotFoundError: [Errno 2] No such file or directory
Exception ignored in: <Finalize object, dead>
Traceback (most recent call last):
  File "/home/ekavvas/.conda/envs/mb_py385/lib/python3.8/multiprocessing/util.py", line 224, in __call__
    res = self._callback(*self._args, **self._kwargs)
  File "/home/ekavvas/.conda/envs/mb_py385/lib/python3.8/site-packages/joblib/externals/loky/backend/synchronize.py", line 102, in _cleanup
    sem_unlink(name)
FileNotFoundError: [Errno 2] No such file or directory
Exception ignored in: <Finalize object, dead>
Traceback (most recent call last):
  File "/home/ekavvas/.conda/envs/mb_py385/lib/python3.8/multiprocessing/util.py", line 224, in __call__
    res = self._callback(*self._args, **self._kwargs)
  File "/home/ekavvas/.conda/envs/mb_py385/lib/python3.8/site-packages/joblib/externals/loky/backend/synchronize.py", line 102, in _cleanup
    sem_unlink(name)
FileNotFoundError: [Errno 2] No such file or directory
Exception ignored in: <Finalize object, dead>
Traceback (most recent call last):
  File "/home/ekavvas/.conda/envs/mb_py385/lib/python3.8/multiprocessing/util.py", line 224, in __call__
    res = self._callback(*self._args, **self._kwargs)
  File "/home/ekavvas/.conda/envs/mb_py385/lib/python3.8/site-packages/joblib/externals/loky/backend/synchronize.py", line 102, in _cleanup
    sem_unlink(name)
FileNotFoundError: [Errno 2] No such file or directory
Exception ignored in: <Finalize object, dead>
Traceback (most recent call last):
  File "/home/ekavvas/.conda/envs/mb_py385/lib/python3.8/multiprocessing/util.py", line 224, in __call__
    res = self._callback(*self._args, **self._kwargs)
  File "/home/ekavvas/.conda/envs/mb_py385/lib/python3.8/site-packages/joblib/externals/loky/backend/synchronize.py", line 102, in _cleanup
    sem_unlink(name)
FileNotFoundError: [Errno 2] No such file or directory
Exception ignored in: <Finalize object, dead>
Traceback (most recent call last):
  File "/home/ekavvas/.conda/envs/mb_py385/lib/python3.8/multiprocessing/util.py", line 224, in __call__
    res = self._callback(*self._args, **self._kwargs)
  File "/home/ekavvas/.conda/envs/mb_py385/lib/python3.8/site-packages/joblib/externals/loky/backend/synchronize.py", line 102, in _cleanup
    sem_unlink(name)
FileNotFoundError: [Errno 2] No such file or directory
Exception ignored in: <Finalize object, dead>
Traceback (most recent call last):
  File "/home/ekavvas/.conda/envs/mb_py385/lib/python3.8/multiprocessing/util.py", line 224, in __call__
    res = self._callback(*self._args, **self._kwargs)
  File "/home/ekavvas/.conda/envs/mb_py385/lib/python3.8/site-packages/joblib/externals/loky/backend/synchronize.py", line 102, in _cleanup
    sem_unlink(name)
FileNotFoundError: [Errno 2] No such file or directory
Exception ignored in: <Finalize object, dead>
Traceback (most recent call last):
  File "/home/ekavvas/.conda/envs/mb_py385/lib/python3.8/multiprocessing/util.py", line 224, in __call__
    res = self._callback(*self._args, **self._kwargs)
  File "/home/ekavvas/.conda/envs/mb_py385/lib/python3.8/site-packages/joblib/externals/loky/backend/synchronize.py", line 102, in _cleanup
    sem_unlink(name)
FileNotFoundError: [Errno 2] No such file or directory
Exception ignored in: <Finalize object, dead>
Traceback (most recent call last):
  File "/home/ekavvas/.conda/envs/mb_py385/lib/python3.8/multiprocessing/util.py", line 224, in __call__
    res = self._callback(*self._args, **self._kwargs)
  File "/home/ekavvas/.conda/envs/mb_py385/lib/python3.8/site-packages/joblib/externals/loky/backend/synchronize.py", line 102, in _cleanup
    sem_unlink(name)
FileNotFoundError: [Errno 2] No such file or directory
Exception ignored in: <Finalize object, dead>
Traceback (most recent call last):
  File "/home/ekavvas/.conda/envs/mb_py385/lib/python3.8/multiprocessing/util.py", line 224, in __call__
    res = self._callback(*self._args, **self._kwargs)
  File "/home/ekavvas/.conda/envs/mb_py385/lib/python3.8/site-packages/joblib/externals/loky/backend/synchronize.py", line 102, in _cleanup
    sem_unlink(name)
FileNotFoundError: [Errno 2] No such file or directory
Exception ignored in: <Finalize object, dead>
Traceback (most recent call last):
  File "/home/ekavvas/.conda/envs/mb_py385/lib/python3.8/multiprocessing/util.py", line 224, in __call__
    res = self._callback(*self._args, **self._kwargs)
  File "/home/ekavvas/.conda/envs/mb_py385/lib/python3.8/site-packages/joblib/externals/loky/backend/synchronize.py", line 102, in _cleanup
    sem_unlink(name)
FileNotFoundError: [Errno 2] No such file or directory
Exception ignored in: <Finalize object, dead>
Traceback (most recent call last):
  File "/home/ekavvas/.conda/envs/mb_py385/lib/python3.8/multiprocessing/util.py", line 224, in __call__
    res = self._callback(*self._args, **self._kwargs)
  File "/home/ekavvas/.conda/envs/mb_py385/lib/python3.8/site-packages/joblib/externals/loky/backend/synchronize.py", line 102, in _cleanup
    sem_unlink(name)
FileNotFoundError: [Errno 2] No such file or directory
Exception ignored in: <Finalize object, dead>
Traceback (most recent call last):
  File "/home/ekavvas/.conda/envs/mb_py385/lib/python3.8/multiprocessing/util.py", line 224, in __call__
    res = self._callback(*self._args, **self._kwargs)
  File "/home/ekavvas/.conda/envs/mb_py385/lib/python3.8/site-packages/joblib/externals/loky/backend/synchronize.py", line 102, in _cleanup
    sem_unlink(name)
FileNotFoundError: [Errno 2] No such file or directory
Exception ignored in: <Finalize object, dead>
Traceback (most recent call last):
  File "/home/ekavvas/.conda/envs/mb_py385/lib/python3.8/multiprocessing/util.py", line 224, in __call__
    res = self._callback(*self._args, **self._kwargs)
  File "/home/ekavvas/.conda/envs/mb_py385/lib/python3.8/site-packages/joblib/externals/loky/backend/synchronize.py", line 102, in _cleanup
    sem_unlink(name)
FileNotFoundError: [Errno 2] No such file or directory
Exception ignored in: <Finalize object, dead>
Traceback (most recent call last):
  File "/home/ekavvas/.conda/envs/mb_py385/lib/python3.8/multiprocessing/util.py", line 224, in __call__
    res = self._callback(*self._args, **self._kwargs)
  File "/home/ekavvas/.conda/envs/mb_py385/lib/python3.8/site-packages/joblib/externals/loky/backend/synchronize.py", line 102, in _cleanup
    sem_unlink(name)
FileNotFoundError: [Errno 2] No such file or directory
Exception ignored in: <Finalize object, dead>
Traceback (most recent call last):
  File "/home/ekavvas/.conda/envs/mb_py385/lib/python3.8/multiprocessing/util.py", line 224, in __call__
    res = self._callback(*self._args, **self._kwargs)
  File "/home/ekavvas/.conda/envs/mb_py385/lib/python3.8/site-packages/joblib/externals/loky/backend/synchronize.py", line 102, in _cleanup
    sem_unlink(name)
FileNotFoundError: [Errno 2] No such file or directory
Exception ignored in: <Finalize object, dead>
Traceback (most recent call last):
  File "/home/ekavvas/.conda/envs/mb_py385/lib/python3.8/multiprocessing/util.py", line 224, in __call__
    res = self._callback(*self._args, **self._kwargs)
  File "/home/ekavvas/.conda/envs/mb_py385/lib/python3.8/site-packages/joblib/externals/loky/backend/synchronize.py", line 102, in _cleanup
    sem_unlink(name)
FileNotFoundError: [Errno 2] No such file or directory
Exception ignored in: <Finalize object, dead>
Traceback (most recent call last):
  File "/home/ekavvas/.conda/envs/mb_py385/lib/python3.8/multiprocessing/util.py", line 224, in __call__
    res = self._callback(*self._args, **self._kwargs)
  File "/home/ekavvas/.conda/envs/mb_py385/lib/python3.8/site-packages/joblib/externals/loky/backend/synchronize.py", line 102, in _cleanup
    sem_unlink(name)
FileNotFoundError: [Errno 2] No such file or directory
Exception ignored in: <Finalize object, dead>
Traceback (most recent call last):
  File "/home/ekavvas/.conda/envs/mb_py385/lib/python3.8/multiprocessing/util.py", line 224, in __call__
    res = self._callback(*self._args, **self._kwargs)
  File "/home/ekavvas/.conda/envs/mb_py385/lib/python3.8/site-packages/joblib/externals/loky/backend/synchronize.py", line 102, in _cleanup
    sem_unlink(name)
FileNotFoundError: [Errno 2] No such file or directory
Exception ignored in: <Finalize object, dead>
Traceback (most recent call last):
  File "/home/ekavvas/.conda/envs/mb_py385/lib/python3.8/multiprocessing/util.py", line 224, in __call__
    res = self._callback(*self._args, **self._kwargs)
  File "/home/ekavvas/.conda/envs/mb_py385/lib/python3.8/site-packages/joblib/externals/loky/backend/synchronize.py", line 102, in _cleanup
    sem_unlink(name)
FileNotFoundError: [Errno 2] No such file or directory
Exception ignored in: <Finalize object, dead>
Traceback (most recent call last):
  File "/home/ekavvas/.conda/envs/mb_py385/lib/python3.8/multiprocessing/util.py", line 224, in __call__
    res = self._callback(*self._args, **self._kwargs)
  File "/home/ekavvas/.conda/envs/mb_py385/lib/python3.8/site-packages/joblib/externals/loky/backend/synchronize.py", line 102, in _cleanup
    sem_unlink(name)
FileNotFoundError: [Errno 2] No such file or directory
Exception ignored in: <Finalize object, dead>
Traceback (most recent call last):
  File "/home/ekavvas/.conda/envs/mb_py385/lib/python3.8/multiprocessing/util.py", line 224, in __call__
    res = self._callback(*self._args, **self._kwargs)
  File "/home/ekavvas/.conda/envs/mb_py385/lib/python3.8/site-packages/joblib/externals/loky/backend/synchronize.py", line 102, in _cleanup
    sem_unlink(name)
FileNotFoundError: [Errno 2] No such file or directory
Exception ignored in: <Finalize object, dead>
Traceback (most recent call last):
  File "/home/ekavvas/.conda/envs/mb_py385/lib/python3.8/multiprocessing/util.py", line 224, in __call__
    res = self._callback(*self._args, **self._kwargs)
  File "/home/ekavvas/.conda/envs/mb_py385/lib/python3.8/site-packages/joblib/externals/loky/backend/synchronize.py", line 102, in _cleanup
    sem_unlink(name)
FileNotFoundError: [Errno 2] No such file or directory
Exception ignored in: <Finalize object, dead>
Traceback (most recent call last):
  File "/home/ekavvas/.conda/envs/mb_py385/lib/python3.8/multiprocessing/util.py", line 224, in __call__
    res = self._callback(*self._args, **self._kwargs)
  File "/home/ekavvas/.conda/envs/mb_py385/lib/python3.8/site-packages/joblib/externals/loky/backend/synchronize.py", line 102, in _cleanup
    sem_unlink(name)
FileNotFoundError: [Errno 2] No such file or directory
Exception ignored in: <Finalize object, dead>
Traceback (most recent call last):
  File "/home/ekavvas/.conda/envs/mb_py385/lib/python3.8/multiprocessing/util.py", line 224, in __call__
    res = self._callback(*self._args, **self._kwargs)
  File "/home/ekavvas/.conda/envs/mb_py385/lib/python3.8/site-packages/joblib/externals/loky/backend/synchronize.py", line 102, in _cleanup
    sem_unlink(name)
FileNotFoundError: [Errno 2] No such file or directory
Exception ignored in: <Finalize object, dead>
Traceback (most recent call last):
  File "/home/ekavvas/.conda/envs/mb_py385/lib/python3.8/multiprocessing/util.py", line 224, in __call__
    res = self._callback(*self._args, **self._kwargs)
  File "/home/ekavvas/.conda/envs/mb_py385/lib/python3.8/site-packages/joblib/externals/loky/backend/synchronize.py", line 102, in _cleanup
    sem_unlink(name)
FileNotFoundError: [Errno 2] No such file or directory
Exception ignored in: <Finalize object, dead>
Traceback (most recent call last):
  File "/home/ekavvas/.conda/envs/mb_py385/lib/python3.8/multiprocessing/util.py", line 224, in __call__
    res = self._callback(*self._args, **self._kwargs)
  File "/home/ekavvas/.conda/envs/mb_py385/lib/python3.8/site-packages/joblib/externals/loky/backend/synchronize.py", line 102, in _cleanup
    sem_unlink(name)
FileNotFoundError: [Errno 2] No such file or directory
Exception ignored in: <Finalize object, dead>
Traceback (most recent call last):
  File "/home/ekavvas/.conda/envs/mb_py385/lib/python3.8/multiprocessing/util.py", line 224, in __call__
    res = self._callback(*self._args, **self._kwargs)
  File "/home/ekavvas/.conda/envs/mb_py385/lib/python3.8/site-packages/joblib/externals/loky/backend/synchronize.py", line 102, in _cleanup
    sem_unlink(name)
FileNotFoundError: [Errno 2] No such file or directory
Exception ignored in: <Finalize object, dead>
Traceback (most recent call last):
  File "/home/ekavvas/.conda/envs/mb_py385/lib/python3.8/multiprocessing/util.py", line 224, in __call__
    res = self._callback(*self._args, **self._kwargs)
  File "/home/ekavvas/.conda/envs/mb_py385/lib/python3.8/site-packages/joblib/externals/loky/backend/synchronize.py", line 102, in _cleanup
    sem_unlink(name)
FileNotFoundError: [Errno 2] No such file or directory
joblib.externals.loky.process_executor._RemoteTraceback: 
"""
Traceback (most recent call last):
  File "/home/ekavvas/.conda/envs/mb_py385/lib/python3.8/site-packages/joblib/externals/loky/process_executor.py", line 407, in _process_worker
    call_item = call_queue.get(block=True, timeout=timeout)
  File "/home/ekavvas/.conda/envs/mb_py385/lib/python3.8/multiprocessing/queues.py", line 116, in get
    return _ForkingPickler.loads(res)
  File "/home/ekavvas/.conda/envs/mb_py385/lib/python3.8/site-packages/joblib/numpy_pickle.py", line 526, in load_temporary_memmap
    obj = load(filename, mmap_mode)
  File "/home/ekavvas/.conda/envs/mb_py385/lib/python3.8/site-packages/joblib/numpy_pickle.py", line 587, in load
    obj = _unpickle(fobj, filename, mmap_mode)
  File "/home/ekavvas/.conda/envs/mb_py385/lib/python3.8/site-packages/joblib/numpy_pickle.py", line 506, in _unpickle
    obj = unpickler.load()
  File "/home/ekavvas/.conda/envs/mb_py385/lib/python3.8/pickle.py", line 1210, in load
    dispatch[key[0]](self)
  File "/home/ekavvas/.conda/envs/mb_py385/lib/python3.8/site-packages/joblib/numpy_pickle.py", line 344, in load_build
    self.stack.append(array_wrapper.read(self))
  File "/home/ekavvas/.conda/envs/mb_py385/lib/python3.8/site-packages/joblib/numpy_pickle.py", line 187, in read
    array = self.read_mmap(unpickler)
  File "/home/ekavvas/.conda/envs/mb_py385/lib/python3.8/site-packages/joblib/numpy_pickle.py", line 160, in read_mmap
    marray = make_memmap(unpickler.filename,
  File "/home/ekavvas/.conda/envs/mb_py385/lib/python3.8/site-packages/joblib/backports.py", line 34, in make_memmap
    mm = np.memmap(filename, dtype=dtype, mode=mode, offset=offset,
  File "/home/ekavvas/.conda/envs/mb_py385/lib/python3.8/site-packages/numpy/core/memmap.py", line 267, in __new__
    mm = mmap.mmap(fid.fileno(), bytes, access=acc, offset=start)
ValueError: mmap length is greater than file size
"""

The above exception was the direct cause of the following exception:

Traceback (most recent call last):
  File "run_hyperparams_aifspc.py", line 130, in <module>
    n_scores = cross_validate(model, X, y, scoring=score_list, cv=skf, n_jobs=-1, error_score='raise')
  File "/home/ekavvas/.conda/envs/mb_py385/lib/python3.8/site-packages/sklearn/model_selection/_validation.py", line 267, in cross_validate
    results = parallel(
  File "/home/ekavvas/.conda/envs/mb_py385/lib/python3.8/site-packages/joblib/parallel.py", line 1056, in __call__
    self.retrieve()
  File "/home/ekavvas/.conda/envs/mb_py385/lib/python3.8/site-packages/joblib/parallel.py", line 935, in retrieve
    self._output.extend(job.get(timeout=self.timeout))
  File "/home/ekavvas/.conda/envs/mb_py385/lib/python3.8/site-packages/joblib/_parallel_backends.py", line 542, in wrap_future_result
    return future.result(timeout=timeout)
  File "/home/ekavvas/.conda/envs/mb_py385/lib/python3.8/concurrent/futures/_base.py", line 439, in result
    return self.__get_result()
  File "/home/ekavvas/.conda/envs/mb_py385/lib/python3.8/concurrent/futures/_base.py", line 388, in __get_result
    raise self._exception
joblib.externals.loky.process_executor.BrokenProcessPool: A task has failed to un-serialize. Please ensure that the arguments of the function are all picklable.
/home/ekavvas/.conda/envs/mb_py385/lib/python3.8/site-packages/joblib/externals/loky/backend/resource_tracker.py:318: UserWarning: resource_tracker: There appear to be 38 leaked semlock objects to clean up at shutdown
  warnings.warn('resource_tracker: There appear to be %d '
/home/ekavvas/.conda/envs/mb_py385/lib/python3.8/site-packages/joblib/externals/loky/backend/resource_tracker.py:333: UserWarning: resource_tracker: /loky-3904987-ffm4l3kc: FileNotFoundError(2, 'No such file or directory')
  warnings.warn('resource_tracker: %s: %r' % (name, e))
/home/ekavvas/.conda/envs/mb_py385/lib/python3.8/site-packages/joblib/externals/loky/backend/resource_tracker.py:333: UserWarning: resource_tracker: /loky-3904987-op9bo3la: FileNotFoundError(2, 'No such file or directory')
  warnings.warn('resource_tracker: %s: %r' % (name, e))
/home/ekavvas/.conda/envs/mb_py385/lib/python3.8/site-packages/joblib/externals/loky/backend/resource_tracker.py:333: UserWarning: resource_tracker: /loky-3904987-0_wnv_qr: FileNotFoundError(2, 'No such file or directory')
  warnings.warn('resource_tracker: %s: %r' % (name, e))
/home/ekavvas/.conda/envs/mb_py385/lib/python3.8/site-packages/joblib/externals/loky/backend/resource_tracker.py:333: UserWarning: resource_tracker: /loky-3904987-57x0wfjc: FileNotFoundError(2, 'No such file or directory')
  warnings.warn('resource_tracker: %s: %r' % (name, e))
/home/ekavvas/.conda/envs/mb_py385/lib/python3.8/site-packages/joblib/externals/loky/backend/resource_tracker.py:333: UserWarning: resource_tracker: /loky-3904987-fhxz6kus: FileNotFoundError(2, 'No such file or directory')
  warnings.warn('resource_tracker: %s: %r' % (name, e))
/home/ekavvas/.conda/envs/mb_py385/lib/python3.8/site-packages/joblib/externals/loky/backend/resource_tracker.py:333: UserWarning: resource_tracker: /loky-3904987-5ii6uay8: FileNotFoundError(2, 'No such file or directory')
  warnings.warn('resource_tracker: %s: %r' % (name, e))
/home/ekavvas/.conda/envs/mb_py385/lib/python3.8/site-packages/joblib/externals/loky/backend/resource_tracker.py:333: UserWarning: resource_tracker: /loky-3904987-no2nch29: FileNotFoundError(2, 'No such file or directory')
  warnings.warn('resource_tracker: %s: %r' % (name, e))
/home/ekavvas/.conda/envs/mb_py385/lib/python3.8/site-packages/joblib/externals/loky/backend/resource_tracker.py:333: UserWarning: resource_tracker: /loky-3904987-sc9drvp6: FileNotFoundError(2, 'No such file or directory')
  warnings.warn('resource_tracker: %s: %r' % (name, e))
/home/ekavvas/.conda/envs/mb_py385/lib/python3.8/site-packages/joblib/externals/loky/backend/resource_tracker.py:333: UserWarning: resource_tracker: /loky-3904987-3cekdcbb: FileNotFoundError(2, 'No such file or directory')
  warnings.warn('resource_tracker: %s: %r' % (name, e))
/home/ekavvas/.conda/envs/mb_py385/lib/python3.8/site-packages/joblib/externals/loky/backend/resource_tracker.py:333: UserWarning: resource_tracker: /loky-3904987-dgfc7hh9: FileNotFoundError(2, 'No such file or directory')
  warnings.warn('resource_tracker: %s: %r' % (name, e))
/home/ekavvas/.conda/envs/mb_py385/lib/python3.8/site-packages/joblib/externals/loky/backend/resource_tracker.py:333: UserWarning: resource_tracker: /loky-3904987-2eqqzukl: FileNotFoundError(2, 'No such file or directory')
  warnings.warn('resource_tracker: %s: %r' % (name, e))
/home/ekavvas/.conda/envs/mb_py385/lib/python3.8/site-packages/joblib/externals/loky/backend/resource_tracker.py:333: UserWarning: resource_tracker: /loky-3904987-hnxyp0wk: FileNotFoundError(2, 'No such file or directory')
  warnings.warn('resource_tracker: %s: %r' % (name, e))
/home/ekavvas/.conda/envs/mb_py385/lib/python3.8/site-packages/joblib/externals/loky/backend/resource_tracker.py:333: UserWarning: resource_tracker: /loky-3904987-e6fr99ux: FileNotFoundError(2, 'No such file or directory')
  warnings.warn('resource_tracker: %s: %r' % (name, e))
/home/ekavvas/.conda/envs/mb_py385/lib/python3.8/site-packages/joblib/externals/loky/backend/resource_tracker.py:333: UserWarning: resource_tracker: /loky-3904987-penvm8i8: FileNotFoundError(2, 'No such file or directory')
  warnings.warn('resource_tracker: %s: %r' % (name, e))
/home/ekavvas/.conda/envs/mb_py385/lib/python3.8/site-packages/joblib/externals/loky/backend/resource_tracker.py:333: UserWarning: resource_tracker: /loky-3904987-rquu1s6h: FileNotFoundError(2, 'No such file or directory')
  warnings.warn('resource_tracker: %s: %r' % (name, e))
/home/ekavvas/.conda/envs/mb_py385/lib/python3.8/site-packages/joblib/externals/loky/backend/resource_tracker.py:333: UserWarning: resource_tracker: /loky-3904987-r1mw_um6: FileNotFoundError(2, 'No such file or directory')
  warnings.warn('resource_tracker: %s: %r' % (name, e))
/home/ekavvas/.conda/envs/mb_py385/lib/python3.8/site-packages/joblib/externals/loky/backend/resource_tracker.py:333: UserWarning: resource_tracker: /loky-3904987-mvyjbmp4: FileNotFoundError(2, 'No such file or directory')
  warnings.warn('resource_tracker: %s: %r' % (name, e))
/home/ekavvas/.conda/envs/mb_py385/lib/python3.8/site-packages/joblib/externals/loky/backend/resource_tracker.py:333: UserWarning: resource_tracker: /loky-3904987-uz8em6x7: FileNotFoundError(2, 'No such file or directory')
  warnings.warn('resource_tracker: %s: %r' % (name, e))
/home/ekavvas/.conda/envs/mb_py385/lib/python3.8/site-packages/joblib/externals/loky/backend/resource_tracker.py:333: UserWarning: resource_tracker: /loky-3904987-w3u68syd: FileNotFoundError(2, 'No such file or directory')
  warnings.warn('resource_tracker: %s: %r' % (name, e))
/home/ekavvas/.conda/envs/mb_py385/lib/python3.8/site-packages/joblib/externals/loky/backend/resource_tracker.py:333: UserWarning: resource_tracker: /loky-3904987-g_4h7j12: FileNotFoundError(2, 'No such file or directory')
  warnings.warn('resource_tracker: %s: %r' % (name, e))
/home/ekavvas/.conda/envs/mb_py385/lib/python3.8/site-packages/joblib/externals/loky/backend/resource_tracker.py:333: UserWarning: resource_tracker: /loky-3904987-o33u1cdr: FileNotFoundError(2, 'No such file or directory')
  warnings.warn('resource_tracker: %s: %r' % (name, e))
/home/ekavvas/.conda/envs/mb_py385/lib/python3.8/site-packages/joblib/externals/loky/backend/resource_tracker.py:333: UserWarning: resource_tracker: /loky-3904987-bi_qaukh: FileNotFoundError(2, 'No such file or directory')
  warnings.warn('resource_tracker: %s: %r' % (name, e))
/home/ekavvas/.conda/envs/mb_py385/lib/python3.8/site-packages/joblib/externals/loky/backend/resource_tracker.py:333: UserWarning: resource_tracker: /loky-3904987-dpbpog6a: FileNotFoundError(2, 'No such file or directory')
  warnings.warn('resource_tracker: %s: %r' % (name, e))
/home/ekavvas/.conda/envs/mb_py385/lib/python3.8/site-packages/joblib/externals/loky/backend/resource_tracker.py:333: UserWarning: resource_tracker: /loky-3904987-wop1hztd: FileNotFoundError(2, 'No such file or directory')
  warnings.warn('resource_tracker: %s: %r' % (name, e))
/home/ekavvas/.conda/envs/mb_py385/lib/python3.8/site-packages/joblib/externals/loky/backend/resource_tracker.py:333: UserWarning: resource_tracker: /loky-3904987-c4iaq31w: FileNotFoundError(2, 'No such file or directory')
  warnings.warn('resource_tracker: %s: %r' % (name, e))
/home/ekavvas/.conda/envs/mb_py385/lib/python3.8/site-packages/joblib/externals/loky/backend/resource_tracker.py:333: UserWarning: resource_tracker: /loky-3904987-c1flhm29: FileNotFoundError(2, 'No such file or directory')
  warnings.warn('resource_tracker: %s: %r' % (name, e))
/home/ekavvas/.conda/envs/mb_py385/lib/python3.8/site-packages/joblib/externals/loky/backend/resource_tracker.py:333: UserWarning: resource_tracker: /loky-3904987-q55i46st: FileNotFoundError(2, 'No such file or directory')
  warnings.warn('resource_tracker: %s: %r' % (name, e))
/home/ekavvas/.conda/envs/mb_py385/lib/python3.8/site-packages/joblib/externals/loky/backend/resource_tracker.py:333: UserWarning: resource_tracker: /loky-3904987-h5wevf0t: FileNotFoundError(2, 'No such file or directory')
  warnings.warn('resource_tracker: %s: %r' % (name, e))
/home/ekavvas/.conda/envs/mb_py385/lib/python3.8/site-packages/joblib/externals/loky/backend/resource_tracker.py:333: UserWarning: resource_tracker: /loky-3904987-tymd7sd7: FileNotFoundError(2, 'No such file or directory')
  warnings.warn('resource_tracker: %s: %r' % (name, e))
/home/ekavvas/.conda/envs/mb_py385/lib/python3.8/site-packages/joblib/externals/loky/backend/resource_tracker.py:333: UserWarning: resource_tracker: /loky-3904987-inn6h5am: FileNotFoundError(2, 'No such file or directory')
  warnings.warn('resource_tracker: %s: %r' % (name, e))
/home/ekavvas/.conda/envs/mb_py385/lib/python3.8/site-packages/joblib/externals/loky/backend/resource_tracker.py:333: UserWarning: resource_tracker: /loky-3904987-c5cj248p: FileNotFoundError(2, 'No such file or directory')
  warnings.warn('resource_tracker: %s: %r' % (name, e))
/home/ekavvas/.conda/envs/mb_py385/lib/python3.8/site-packages/joblib/externals/loky/backend/resource_tracker.py:333: UserWarning: resource_tracker: /loky-3904987-6_12k2th: FileNotFoundError(2, 'No such file or directory')
  warnings.warn('resource_tracker: %s: %r' % (name, e))
/home/ekavvas/.conda/envs/mb_py385/lib/python3.8/site-packages/joblib/externals/loky/backend/resource_tracker.py:333: UserWarning: resource_tracker: /loky-3904987-9dy6dlnh: FileNotFoundError(2, 'No such file or directory')
  warnings.warn('resource_tracker: %s: %r' % (name, e))
/home/ekavvas/.conda/envs/mb_py385/lib/python3.8/site-packages/joblib/externals/loky/backend/resource_tracker.py:333: UserWarning: resource_tracker: /loky-3904987-nz4reili: FileNotFoundError(2, 'No such file or directory')
  warnings.warn('resource_tracker: %s: %r' % (name, e))
/home/ekavvas/.conda/envs/mb_py385/lib/python3.8/site-packages/joblib/externals/loky/backend/resource_tracker.py:333: UserWarning: resource_tracker: /loky-3904987-de8cbvy_: FileNotFoundError(2, 'No such file or directory')
  warnings.warn('resource_tracker: %s: %r' % (name, e))
/home/ekavvas/.conda/envs/mb_py385/lib/python3.8/site-packages/joblib/externals/loky/backend/resource_tracker.py:333: UserWarning: resource_tracker: /loky-3904987-0ytvbwl1: FileNotFoundError(2, 'No such file or directory')
  warnings.warn('resource_tracker: %s: %r' % (name, e))
/home/ekavvas/.conda/envs/mb_py385/lib/python3.8/site-packages/joblib/externals/loky/backend/resource_tracker.py:333: UserWarning: resource_tracker: /loky-3904987-87bftqto: FileNotFoundError(2, 'No such file or directory')
  warnings.warn('resource_tracker: %s: %r' % (name, e))
/home/ekavvas/.conda/envs/mb_py385/lib/python3.8/site-packages/joblib/externals/loky/backend/resource_tracker.py:333: UserWarning: resource_tracker: /loky-3904987-9dywk60a: FileNotFoundError(2, 'No such file or directory')
  warnings.warn('resource_tracker: %s: %r' % (name, e))
